<?xml version="1.0" ?>
<!-- =================================================================================== -->
<!-- |    This document was autogenerated by xacro from /home/robot/B_workspace/dual_robot/src/dual_arm/arm_robot/arm_robot_description/urdf/dual_arm_robot.xacro | -->
<!-- |    EDITING THIS FILE BY HAND IS NOT RECOMMENDED                                 | -->
<!-- =================================================================================== -->
<robot name="ur5e_robot">
    <material name="grey">
        <color rgba="0.5 0.5 0.5 1.0" />
    </material>
    <link name="world" />
    <link name="body_base_link">
        <inertial>
            <origin rpy="0 0 0" xyz="-1.72E-06 -0.00094189 0.44814" />
            <mass value="5.3997" />
            <inertia ixx="0.18584" ixy="-3.9082E-07" ixz="-1.5348E-07" iyy="0.24302" iyz="-4.7491E-05" izz="0.069032" />
        </inertial>
        <visual>
            <origin rpy="0 0 0" xyz="0 0 0" />
            <geometry>
                <mesh filename="package://ur_gazebo/meshes/body/body_link.STL" />
            </geometry>
            <material name="">
                <color rgba="1 1 1 1" />
            </material>
        </visual>
        <collision>
            <origin rpy="0 0 0" xyz="0 0 0" />
            <geometry>
                <mesh filename="package://ur_gazebo/meshes/body/body_link.STL" />
            </geometry>
        </collision>
    </link>
    <link name="body_right_base_link">
        <inertial>
            <origin rpy="0 0 0" xyz="1.446E-05 0.063848 -0.00090827" />
            <mass value="0.65565" />
            <inertia ixx="0.0011999" ixy="5.6587E-07" ixz="8.9252E-08" iyy="0.001589" iyz="-2.2042E-05" izz="0.001245" />
        </inertial>
        <!-- <visual>
      <origin
        xyz="0 0 0"
        rpy="0 0 0" />
      <geometry>
        <mesh
          filename="package://ur_gazebo/meshes/body/meshes/right_arm_fixed_link.STL" />
      </geometry>
      <material
        name="">
        <color
          rgba="1 1 1 1" />
      </material>
    </visual>
    <collision>
      <origin
        xyz="0 0 0"
        rpy="0 0 0" />
      <geometry>
        <mesh
          filename="package://ur_gazebo/meshes/body/meshes/right_arm_fixed_link.STL" />
      </geometry>
    </collision> -->
    </link>
    <joint name="right_arm_fixed_joint" type="fixed">
        <origin rpy="-0.95532 -0.5236 2.1863" xyz="-0.17475 0 0.64111" />
        <parent link="body_base_link" />
        <child link="body_right_base_link" />
        <axis xyz="0 0 0" />
    </joint>
    <link name="body_left_base_link">
        <inertial>
            <origin rpy="0 0 0" xyz="1.446E-05 0.053848 -0.00090827" />
            <mass value="0.65565" />
            <inertia ixx="0.0011999" ixy="5.6587E-07" ixz="8.9252E-08" iyy="0.001589" iyz="-2.2042E-05" izz="0.001245" />
        </inertial>
        <!-- <visual>
      <origin
        xyz="0 0 0"
        rpy="0 0 0" />
      <geometry>
        <mesh
          filename="package://ur_gazebo/meshes/body/meshes/left_arm_fixed_link.STL" />
      </geometry>
      <material
        name="">
        <color
          rgba="1 1 1 1" />
      </material>
    </visual>
    <collision>
      <origin
        xyz="0 0 0"
        rpy="0 0 0" />
      <geometry>
        <mesh
          filename="package://ur_gazebo/meshes/body/meshes/left_arm_fixed_link.STL" />
      </geometry>
    </collision> -->
    </link>
    <joint name="left_arm_fixed_joint" type="fixed">
        <origin rpy="-0.95532 0.5236 -2.1863" xyz="0.18182 0 0.63404" />
        <parent link="body_base_link" />
        <child link="body_left_base_link" />
        <axis xyz="0 0 0" />
    </joint>
    <link name="bozi_link">
        <inertial>
            <origin rpy="0 0 0" xyz="-0.02368 -0.062099 -0.0468" />
            <mass value="0.5717" />
            <inertia ixx="0.0043319" ixy="-0.0007239" ixz="-3.3674E-09" iyy="0.00074141" iyz="2.8419E-09" izz="0.0044017" />
        </inertial>
        <visual>
            <origin rpy="0 0 0" xyz="0 0 0" />
            <geometry>
                <mesh filename="package://ur_gazebo/meshes/body/bozi_link.STL" />
            </geometry>
            <material name="">
                <color rgba="0.066667 0.6 0.29804 1" />
            </material>
        </visual>
        <collision>
            <origin rpy="0 0 0" xyz="0 0 0" />
            <geometry>
                <mesh filename="package://ur_gazebo/meshes/body/bozi_link.STL" />
            </geometry>
        </collision>
    </link>
    <joint name="bozi_joint" type="fixed">
        <origin rpy="1.5708 0 -1.5708" xyz="-0.0468 -0.045 0.91925" />
        <parent link="body_base_link" />
        <child link="bozi_link" />
        <axis xyz="0 0 0" />
    </joint>
    <joint name="body_base_joint" type="fixed">
        <parent link="world" />
        <child link="body_base_link" />
        <origin rpy="0 0 3.1415926" xyz="0 0 0" />
        <axis xyz="0 0 0" />
    </joint>
    <!-- 对于底座的描述 -->
    <link name="base_link">
        <inertial>
            <origin rpy="0 0 0" xyz="-1.4069E-17 0 0.40258" />
            <mass value="400.99" />
            <inertia ixx="46.843" ixy="-1.8381E-16" ixz="-1.5044E-15" iyy="31.456" iyz="2.1237E-15" izz="38.411" />
        </inertial>
        <visual>
            <origin rpy="0 0 0" xyz="0 0 0" />
            <geometry>
                <mesh filename="package://ur_gazebo/meshes/base/base_link.STL" />
            </geometry>
            <material name="">
                <color rgba="0.066667 0.6 0.29804 1" />
            </material>
        </visual>
        <collision>
            <origin rpy="0 0 0" xyz="0 0 0" />
            <geometry>
                <mesh filename="package://ur_gazebo/meshes/base/base_link.STL" />
            </geometry>
        </collision>
    </link>
    <!-- ################################### -->
    <joint name="base_joint" type="fixed">
        <parent link="world" />
        <child link="base_link" />
        <origin rpy="0.0 0.0 0.0" xyz="0 0.26 -0.78" />
    </joint>
    <link name="head_link">
        <inertial>
            <origin rpy="0 0 0" xyz="0.10509 0.0025699 -0.046837" />
            <mass value="2.8418" />
            <inertia ixx="0.02624" ixy="-0.00030059" ixz="-2.3615E-08" iyy="0.016373" iyz="4.8178E-07" izz="0.011367" />
        </inertial>
        <visual>
            <origin rpy="0 0 0" xyz="0 0 0" />
            <geometry>
                <mesh filename="package://ur_gazebo/meshes/head/head_link.STL" />
            </geometry>
            <material name="">
                <color rgba="0.89804 0.82745 0.11765 1" />
            </material>
        </visual>
        <collision>
            <origin rpy="0 0 0" xyz="0 0 0" />
            <geometry>
                <mesh filename="package://ur_gazebo/meshes/head/head_link.STL" />
            </geometry>
        </collision>
    </link>
    <link name="camera_fixed_link">
        <inertial>
            <origin rpy="0 0 0" xyz="0.00017347 0.027417 0.04176" />
            <mass value="0.057939" />
            <inertia ixx="3.4645E-05" ixy="1.3474E-09" ixz="4.6377E-07" iyy="6.3455E-06" iyz="4.0965E-07" izz="3.348E-05" />
        </inertial>
        <visual>
            <origin rpy="0 0 0" xyz="0 0 0" />
            <geometry>
                <mesh filename="package://ur_gazebo/meshes/head/camera_fixed_link.STL" />
            </geometry>
            <material name="">
                <color rgba="0.066667 0.6 0.29804 1" />
            </material>
        </visual>
        <collision>
            <origin rpy="0 0 0" xyz="0 0 0" />
            <geometry>
                <mesh filename="package://ur_gazebo/meshes/head/camera_fixed_link.STL" />
            </geometry>
        </collision>
    </link>
    <joint name="camera_fixed_joint" type="fixed">
        <origin rpy="-1.5708 0 -2.0943951" xyz="0.10034 0.16948 -0.0168" />
        <parent link="head_link" />
        <child link="camera_fixed_link" />
        <axis xyz="0 0 0" />
    </joint>
    <joint name="head_body_joint" type="fixed">
        <parent link="bozi_link" />
        <child link="head_link" />
        <origin rpy="0 0 -0.1" xyz="0 0 0" />
        <axis xyz="0 0 0" />
    </joint>
    <!-- 右机械臂 -->
    <link name="right_correct_link" />
    <joint name="right_correct_joint" type="fixed">
        <parent link="body_right_base_link" />
        <child link="right_correct_link" />
        <origin rpy="-1.5707963 -2.35619448975 0.0" xyz="0 0 0" />
        <!-- <origin xyz="0 0 0" rpy="-1.5707963 2.35619448975 0.0" /> -->
    </joint>
    <!--
    Base UR robot series xacro macro.

    NOTE: this is NOT a URDF. It cannot directly be loaded by consumers
    expecting a flattened '.urdf' file. See the top-level '.xacro' for that
    (but note: that .xacro must still be processed by the xacro command).

    For use in '.launch' files: use one of the 'load_urX.launch' convenience
    launch files.

    This file models the base kinematic chain of a UR robot, which then gets
    parameterised by various configuration files to convert it into a UR3(e),
    UR5(e), UR10(e) or UR16e.

    NOTE: the default kinematic parameters (ie: link lengths, frame locations,
    offets, etc) do not correspond to any particular robot. They are defaults
    only. There WILL be non-zero offsets between the Forward Kinematics results
    in TF (ie: robot_state_publisher) and the values reported by the Teach
    Pendant.

    For accurate (and robot-specific) transforms, the 'kinematics_parameters_file'
    parameter MUST point to a .yaml file containing the appropriate values for
    the targetted robot.

    If using the UniversalRobots/Universal_Robots_ROS_Driver, follow the steps
    described in the readme of that repository to extract the kinematic
    calibration from the controller and generate the required .yaml file.

    Main author of the migration to yaml configs: Ludovic Delval.

    Contributors to previous versions (in no particular order):

     - Felix Messmer
     - Kelsey Hawkins
     - Wim Meeussen
     - Shaun Edwards
     - Nadia Hammoudeh Garcia
     - Dave Hershberger
     - G. vd. Hoorn
     - Philip Long
     - Dave Coleman
     - Miguel Prada
     - Mathias Luedtke
     - Marcel Schnirring
     - Felix von Drigalski
     - Felix Exner
     - Jimmy Da Silva
     - Ajit Krisshna N L
     - Muhammad Asif Rana
  -->
    <!--
    NOTE: the macro defined in this file is NOT part of the public API of this
          package. Users CANNOT rely on this file being available, or stored in
          this location. Nor can they rely on the existence of the macro.
  -->
    <transmission name="right_shoulder_pan_trans">
        <type>transmission_interface/SimpleTransmission</type>
        <joint name="right_shoulder_pan_joint">
            <hardwareInterface>hardware_interface/PositionJointInterface</hardwareInterface>
        </joint>
        <actuator name="right_shoulder_pan_motor">
            <mechanicalReduction>1</mechanicalReduction>
            <hardwareInterface>hardware_interface/EffortJointInterface</hardwareInterface>
        </actuator>
    </transmission>
    <transmission name="right_shoulder_lift_trans">
        <type>transmission_interface/SimpleTransmission</type>
        <joint name="right_shoulder_lift_joint">
            <hardwareInterface>hardware_interface/PositionJointInterface</hardwareInterface>
        </joint>
        <actuator name="right_shoulder_lift_motor">
            <mechanicalReduction>1</mechanicalReduction>
            <hardwareInterface>hardware_interface/EffortJointInterface</hardwareInterface>
        </actuator>
    </transmission>
    <transmission name="right_elbow_trans">
        <type>transmission_interface/SimpleTransmission</type>
        <joint name="right_elbow_joint">
            <hardwareInterface>hardware_interface/PositionJointInterface</hardwareInterface>
        </joint>
        <actuator name="right_elbow_motor">
            <mechanicalReduction>1</mechanicalReduction>
            <hardwareInterface>hardware_interface/EffortJointInterface</hardwareInterface>
        </actuator>
    </transmission>
    <transmission name="right_wrist_1_trans">
        <type>transmission_interface/SimpleTransmission</type>
        <joint name="right_wrist_1_joint">
            <hardwareInterface>hardware_interface/PositionJointInterface</hardwareInterface>
        </joint>
        <actuator name="right_wrist_1_motor">
            <mechanicalReduction>1</mechanicalReduction>
            <hardwareInterface>hardware_interface/EffortJointInterface</hardwareInterface>
        </actuator>
    </transmission>
    <transmission name="right_wrist_2_trans">
        <type>transmission_interface/SimpleTransmission</type>
        <joint name="right_wrist_2_joint">
            <hardwareInterface>hardware_interface/PositionJointInterface</hardwareInterface>
        </joint>
        <actuator name="right_wrist_2_motor">
            <mechanicalReduction>1</mechanicalReduction>
            <hardwareInterface>hardware_interface/EffortJointInterface</hardwareInterface>
        </actuator>
    </transmission>
    <transmission name="right_wrist_3_trans">
        <type>transmission_interface/SimpleTransmission</type>
        <joint name="right_wrist_3_joint">
            <hardwareInterface>hardware_interface/PositionJointInterface</hardwareInterface>
        </joint>
        <actuator name="right_wrist_3_motor">
            <mechanicalReduction>1</mechanicalReduction>
            <hardwareInterface>hardware_interface/EffortJointInterface</hardwareInterface>
        </actuator>
    </transmission>
    <!-- links: main serial chain -->
    <link name="right_base_link" />
    <link name="right_base_link_inertia">
        <visual>
            <origin rpy="0 0 3.141592653589793" xyz="0 0 0" />
            <geometry>
                <mesh filename="package://arm_robot_description/meshes/ur5e/visual/base.dae" />
            </geometry>
            <material name="LightGrey">
                <color rgba="0.7 0.7 0.7 1.0" />
            </material>
        </visual>
        <collision>
            <origin rpy="0 0 3.141592653589793" xyz="0 0 0" />
            <geometry>
                <mesh filename="package://arm_robot_description/meshes/ur5e/collision/base.stl" />
            </geometry>
        </collision>
        <inertial>
            <mass value="4.0" />
            <origin rpy="0 0 0" xyz="0 0 0" />
            <inertia ixx="0.00443333156" ixy="0.0" ixz="0.0" iyy="0.00443333156" iyz="0.0" izz="0.0072" />
        </inertial>
    </link>
    <link name="right_shoulder_link">
        <visual>
            <origin rpy="0 0 3.141592653589793" xyz="0 0 0" />
            <geometry>
                <mesh filename="package://arm_robot_description/meshes/ur5e/visual/shoulder.dae" />
            </geometry>
            <material name="LightGrey">
                <color rgba="0.7 0.7 0.7 1.0" />
            </material>
        </visual>
        <collision>
            <origin rpy="0 0 3.141592653589793" xyz="0 0 0" />
            <geometry>
                <mesh filename="package://arm_robot_description/meshes/ur5e/collision/shoulder.stl" />
            </geometry>
        </collision>
        <inertial>
            <mass value="3.7" />
            <origin rpy="0 0 0" xyz="0 0 0" />
            <inertia ixx="0.010267495893" ixy="0.0" ixz="0.0" iyy="0.010267495893" iyz="0.0" izz="0.00666" />
        </inertial>
    </link>
    <link name="right_upper_arm_link">
        <visual>
            <origin rpy="1.5707963267948966 0 -1.5707963267948966" xyz="0 0 0.138" />
            <geometry>
                <mesh filename="package://arm_robot_description/meshes/ur5e/visual/upperarm.dae" />
            </geometry>
            <material name="LightGrey">
                <color rgba="0.7 0.7 0.7 1.0" />
            </material>
        </visual>
        <collision>
            <origin rpy="1.5707963267948966 0 -1.5707963267948966" xyz="0 0 0.138" />
            <geometry>
                <mesh filename="package://arm_robot_description/meshes/ur5e/collision/upperarm.stl" />
            </geometry>
        </collision>
        <inertial>
            <mass value="8.393" />
            <origin rpy="0 1.5707963267948966 0" xyz="-0.2125 0.0 0.138" />
            <inertia ixx="0.1338857818623325" ixy="0.0" ixz="0.0" iyy="0.1338857818623325" iyz="0.0" izz="0.0151074" />
        </inertial>
    </link>
    <link name="right_forearm_link">
        <visual>
            <origin rpy="1.5707963267948966 0 -1.5707963267948966" xyz="0 0 0.007" />
            <geometry>
                <mesh filename="package://arm_robot_description/meshes/ur5e/visual/forearm.dae" />
            </geometry>
            <material name="LightGrey">
                <color rgba="0.7 0.7 0.7 1.0" />
            </material>
        </visual>
        <collision>
            <origin rpy="1.5707963267948966 0 -1.5707963267948966" xyz="0 0 0.007" />
            <geometry>
                <mesh filename="package://arm_robot_description/meshes/ur5e/collision/forearm.stl" />
            </geometry>
        </collision>
        <inertial>
            <mass value="2.275" />
            <origin rpy="0 1.5707963267948966 0" xyz="-0.1961 0.0 0.007" />
            <inertia ixx="0.031209355099586295" ixy="0.0" ixz="0.0" iyy="0.031209355099586295" iyz="0.0" izz="0.004095" />
        </inertial>
    </link>
    <link name="right_wrist_1_link">
        <visual>
            <!-- TODO: Move this to a parameter -->
            <origin rpy="1.5707963267948966 0 0" xyz="0 0 -0.127" />
            <geometry>
                <mesh filename="package://arm_robot_description/meshes/ur5e/visual/wrist1.dae" />
            </geometry>
            <material name="LightGrey">
                <color rgba="0.7 0.7 0.7 1.0" />
            </material>
        </visual>
        <collision>
            <origin rpy="1.5707963267948966 0 0" xyz="0 0 -0.127" />
            <geometry>
                <mesh filename="package://arm_robot_description/meshes/ur5e/collision/wrist1.stl" />
            </geometry>
        </collision>
        <inertial>
            <mass value="1.219" />
            <origin rpy="0 0 0" xyz="0 0 0" />
            <inertia ixx="0.0025598989760400002" ixy="0.0" ixz="0.0" iyy="0.0025598989760400002" iyz="0.0" izz="0.0021942" />
        </inertial>
    </link>
    <link name="right_wrist_2_link">
        <visual>
            <origin rpy="0 0 0" xyz="0 0 -0.0997" />
            <geometry>
                <mesh filename="package://arm_robot_description/meshes/ur5e/visual/wrist2.dae" />
            </geometry>
            <material name="LightGrey">
                <color rgba="0.7 0.7 0.7 1.0" />
            </material>
        </visual>
        <collision>
            <origin rpy="0 0 0" xyz="0 0 -0.0997" />
            <geometry>
                <mesh filename="package://arm_robot_description/meshes/ur5e/collision/wrist2.stl" />
            </geometry>
        </collision>
        <inertial>
            <mass value="1.219" />
            <origin rpy="0 0 0" xyz="0 0 0" />
            <inertia ixx="0.0025598989760400002" ixy="0.0" ixz="0.0" iyy="0.0025598989760400002" iyz="0.0" izz="0.0021942" />
        </inertial>
    </link>
    <link name="right_wrist_3_link">
        <visual>
            <origin rpy="1.5707963267948966 0 0" xyz="0 0 -0.0989" />
            <geometry>
                <mesh filename="package://arm_robot_description/meshes/ur5e/visual/wrist3.dae" />
            </geometry>
            <material name="LightGrey">
                <color rgba="0.7 0.7 0.7 1.0" />
            </material>
        </visual>
        <collision>
            <origin rpy="1.5707963267948966 0 0" xyz="0 0 -0.0989" />
            <geometry>
                <mesh filename="package://arm_robot_description/meshes/ur5e/collision/wrist3.stl" />
            </geometry>
        </collision>
        <inertial>
            <mass value="0.1879" />
            <origin rpy="0 0 0" xyz="0.0 0.0 -0.0229" />
            <inertia ixx="9.890410052167731e-05" ixy="0.0" ixz="0.0" iyy="9.890410052167731e-05" iyz="0.0" izz="0.0001321171875" />
        </inertial>
    </link>
    <!-- joints: main serial chain -->
    <joint name="right_base_link-base_link_inertia" type="fixed">
        <parent link="right_base_link" />
        <child link="right_base_link_inertia" />
        <!-- 'base_link' is REP-103 aligned (so X+ forward), while the internal
           frames of the robot/controller have X+ pointing backwards.
           Use the joint between 'base_link' and 'base_link_inertia' (a dummy
           link/frame) to introduce the necessary rotation over Z (of pi rad).
      -->
        <origin rpy="0 0 3.141592653589793" xyz="0 0 0" />
    </joint>
    <joint name="right_shoulder_pan_joint" type="revolute">
        <parent link="right_base_link_inertia" />
        <child link="right_shoulder_link" />
        <origin rpy="0 0 5.921646436743422e-08" xyz="0 0 0.1627297657342701" />
        <axis xyz="0 0 1" />
        <limit effort="150.0" lower="-6.283185307179586" upper="6.283185307179586" velocity="3.141592653589793" />
        <dynamics damping="0" friction="0" />
    </joint>
    <joint name="right_shoulder_lift_joint" type="revolute">
        <parent link="right_shoulder_link" />
        <child link="right_upper_arm_link" />
        <origin rpy="1.571350908778415 0 -3.085572842734852e-06" xyz="0.0001588353640365326 0 0" />
        <axis xyz="0 0 1" />
        <limit effort="150.0" lower="-6.283185307179586" upper="6.283185307179586" velocity="3.141592653589793" />
        <dynamics damping="0" friction="0" />
    </joint>
    <joint name="right_elbow_joint" type="revolute">
        <parent link="right_upper_arm_link" />
        <child link="right_forearm_link" />
        <origin rpy="0.0003200011350069759 -0.0002227248904285447 -1.085352311177093e-06" xyz="-0.4251005603256471 0 0" />
        <axis xyz="0 0 1" />
        <limit effort="150.0" lower="-3.141592653589793" upper="3.141592653589793" velocity="3.141592653589793" />
        <dynamics damping="0" friction="0" />
    </joint>
    <joint name="right_wrist_1_joint" type="revolute">
        <parent link="right_forearm_link" />
        <child link="right_wrist_1_link" />
        <origin rpy="0.007922150818238065 0.0001913312126438064 -2.456957013920244e-06" xyz="-0.3922314444721665 -0.001059811827050482 0.1337754960543269" />
        <axis xyz="0 0 1" />
        <limit effort="28.0" lower="-6.283185307179586" upper="6.283185307179586" velocity="3.141592653589793" />
        <dynamics damping="0" friction="0" />
    </joint>
    <joint name="right_wrist_2_joint" type="revolute">
        <parent link="right_wrist_1_link" />
        <child link="right_wrist_2_link" />
        <origin rpy="1.569787769915148 0 4.196170326140058e-08" xyz="-8.543141610977271e-05 -0.09959947723388803 0.0001004517720430495" />
        <axis xyz="0 0 1" />
        <limit effort="28.0" lower="-6.283185307179586" upper="6.283185307179586" velocity="3.141592653589793" />
        <dynamics damping="0" friction="0" />
    </joint>
    <joint name="right_wrist_3_joint" type="revolute">
        <parent link="right_wrist_2_link" />
        <child link="right_wrist_3_link" />
        <origin rpy="1.570601435882507 3.141592653589793 3.141592438200498" xyz="7.159022188747432e-05 0.09955984828462842 -1.940330991524593e-05" />
        <axis xyz="0 0 1" />
        <limit effort="28.0" lower="-6.283185307179586" upper="6.283185307179586" velocity="3.141592653589793" />
        <dynamics damping="0" friction="0" />
    </joint>
    <!-- ROS-Industrial 'base' frame: base_link to UR 'Base' Coordinates transform -->
    <link name="right_base" />
    <joint name="right_base_link-base_fixed_joint" type="fixed">
        <!-- Note the rotation over Z of pi radians: as base_link is REP-103
           aligned (ie: has X+ forward, Y+ left and Z+ up), this is needed
           to correctly align 'base' with the 'Base' coordinate system of
           the UR controller.
      -->
        <origin rpy="0 0 3.141592653589793" xyz="0 0 0" />
        <parent link="right_base_link" />
        <child link="right_base" />
    </joint>
    <!-- ROS-Industrial 'flange' frame: attachment point for EEF models -->
    <link name="right_flange" />
    <joint name="right_wrist_3-flange" type="fixed">
        <parent link="right_wrist_3_link" />
        <child link="right_flange" />
        <origin rpy="0 -1.5707963267948966 -1.5707963267948966" xyz="0 0 0" />
    </joint>
    <!-- ROS-Industrial 'tool0' frame: all-zeros tool frame -->
    <link name="right_tool0" />
    <joint name="right_flange-tool0" type="fixed">
        <!-- default toolframe: X+ left, Y+ up, Z+ front -->
        <origin rpy="1.5707963267948966 0 1.5707963267948966" xyz="0.0 0 0" />
        <parent link="right_flange" />
        <child link="right_tool0" />
    </joint>
    <joint name="right_virtual_fixed" type="fixed">
        <parent link="right_correct_link" />
        <child link="right_base_link" />
        <!-- 虚拟关节修正 -->
        <origin rpy="0.0 0.0 0.0" xyz="0.0 0.0 0.0" />
    </joint>
    <!-- 左机械臂 -->
    <link name="left_correct_link" />
    <joint name="left_correct_joint" type="fixed">
        <parent link="body_left_base_link" />
        <child link="left_correct_link" />
        <origin rpy="-1.5707963 -0.7853977 0.0" xyz="0 0 0" />
        <!-- <origin xyz="0 0 0" rpy="-1.5707963 -2.35619448975 0.0" /> -->
    </joint>
    <!--
    Base UR robot series xacro macro.

    NOTE: this is NOT a URDF. It cannot directly be loaded by consumers
    expecting a flattened '.urdf' file. See the top-level '.xacro' for that
    (but note: that .xacro must still be processed by the xacro command).

    For use in '.launch' files: use one of the 'load_urX.launch' convenience
    launch files.

    This file models the base kinematic chain of a UR robot, which then gets
    parameterised by various configuration files to convert it into a UR3(e),
    UR5(e), UR10(e) or UR16e.

    NOTE: the default kinematic parameters (ie: link lengths, frame locations,
    offets, etc) do not correspond to any particular robot. They are defaults
    only. There WILL be non-zero offsets between the Forward Kinematics results
    in TF (ie: robot_state_publisher) and the values reported by the Teach
    Pendant.

    For accurate (and robot-specific) transforms, the 'kinematics_parameters_file'
    parameter MUST point to a .yaml file containing the appropriate values for
    the targetted robot.

    If using the UniversalRobots/Universal_Robots_ROS_Driver, follow the steps
    described in the readme of that repository to extract the kinematic
    calibration from the controller and generate the required .yaml file.

    Main author of the migration to yaml configs: Ludovic Delval.

    Contributors to previous versions (in no particular order):

     - Felix Messmer
     - Kelsey Hawkins
     - Wim Meeussen
     - Shaun Edwards
     - Nadia Hammoudeh Garcia
     - Dave Hershberger
     - G. vd. Hoorn
     - Philip Long
     - Dave Coleman
     - Miguel Prada
     - Mathias Luedtke
     - Marcel Schnirring
     - Felix von Drigalski
     - Felix Exner
     - Jimmy Da Silva
     - Ajit Krisshna N L
     - Muhammad Asif Rana
  -->
    <!--
    NOTE: the macro defined in this file is NOT part of the public API of this
          package. Users CANNOT rely on this file being available, or stored in
          this location. Nor can they rely on the existence of the macro.
  -->
    <transmission name="left_shoulder_pan_trans">
        <type>transmission_interface/SimpleTransmission</type>
        <joint name="left_shoulder_pan_joint">
            <hardwareInterface>hardware_interface/PositionJointInterface</hardwareInterface>
        </joint>
        <actuator name="left_shoulder_pan_motor">
            <mechanicalReduction>1</mechanicalReduction>
            <hardwareInterface>hardware_interface/EffortJointInterface</hardwareInterface>
        </actuator>
    </transmission>
    <transmission name="left_shoulder_lift_trans">
        <type>transmission_interface/SimpleTransmission</type>
        <joint name="left_shoulder_lift_joint">
            <hardwareInterface>hardware_interface/PositionJointInterface</hardwareInterface>
        </joint>
        <actuator name="left_shoulder_lift_motor">
            <mechanicalReduction>1</mechanicalReduction>
            <hardwareInterface>hardware_interface/EffortJointInterface</hardwareInterface>
        </actuator>
    </transmission>
    <transmission name="left_elbow_trans">
        <type>transmission_interface/SimpleTransmission</type>
        <joint name="left_elbow_joint">
            <hardwareInterface>hardware_interface/PositionJointInterface</hardwareInterface>
        </joint>
        <actuator name="left_elbow_motor">
            <mechanicalReduction>1</mechanicalReduction>
            <hardwareInterface>hardware_interface/EffortJointInterface</hardwareInterface>
        </actuator>
    </transmission>
    <transmission name="left_wrist_1_trans">
        <type>transmission_interface/SimpleTransmission</type>
        <joint name="left_wrist_1_joint">
            <hardwareInterface>hardware_interface/PositionJointInterface</hardwareInterface>
        </joint>
        <actuator name="left_wrist_1_motor">
            <mechanicalReduction>1</mechanicalReduction>
            <hardwareInterface>hardware_interface/EffortJointInterface</hardwareInterface>
        </actuator>
    </transmission>
    <transmission name="left_wrist_2_trans">
        <type>transmission_interface/SimpleTransmission</type>
        <joint name="left_wrist_2_joint">
            <hardwareInterface>hardware_interface/PositionJointInterface</hardwareInterface>
        </joint>
        <actuator name="left_wrist_2_motor">
            <mechanicalReduction>1</mechanicalReduction>
            <hardwareInterface>hardware_interface/EffortJointInterface</hardwareInterface>
        </actuator>
    </transmission>
    <transmission name="left_wrist_3_trans">
        <type>transmission_interface/SimpleTransmission</type>
        <joint name="left_wrist_3_joint">
            <hardwareInterface>hardware_interface/PositionJointInterface</hardwareInterface>
        </joint>
        <actuator name="left_wrist_3_motor">
            <mechanicalReduction>1</mechanicalReduction>
            <hardwareInterface>hardware_interface/EffortJointInterface</hardwareInterface>
        </actuator>
    </transmission>
    <!-- links: main serial chain -->
    <link name="left_base_link" />
    <link name="left_base_link_inertia">
        <visual>
            <origin rpy="0 0 3.141592653589793" xyz="0 0 0" />
            <geometry>
                <mesh filename="package://arm_robot_description/meshes/ur5e/visual/base.dae" />
            </geometry>
            <material name="LightGrey">
                <color rgba="0.7 0.7 0.7 1.0" />
            </material>
        </visual>
        <collision>
            <origin rpy="0 0 3.141592653589793" xyz="0 0 0" />
            <geometry>
                <mesh filename="package://arm_robot_description/meshes/ur5e/collision/base.stl" />
            </geometry>
        </collision>
        <inertial>
            <mass value="4.0" />
            <origin rpy="0 0 0" xyz="0 0 0" />
            <inertia ixx="0.00443333156" ixy="0.0" ixz="0.0" iyy="0.00443333156" iyz="0.0" izz="0.0072" />
        </inertial>
    </link>
    <link name="left_shoulder_link">
        <visual>
            <origin rpy="0 0 3.141592653589793" xyz="0 0 0" />
            <geometry>
                <mesh filename="package://arm_robot_description/meshes/ur5e/visual/shoulder.dae" />
            </geometry>
            <material name="LightGrey">
                <color rgba="0.7 0.7 0.7 1.0" />
            </material>
        </visual>
        <collision>
            <origin rpy="0 0 3.141592653589793" xyz="0 0 0" />
            <geometry>
                <mesh filename="package://arm_robot_description/meshes/ur5e/collision/shoulder.stl" />
            </geometry>
        </collision>
        <inertial>
            <mass value="3.7" />
            <origin rpy="0 0 0" xyz="0 0 0" />
            <inertia ixx="0.010267495893" ixy="0.0" ixz="0.0" iyy="0.010267495893" iyz="0.0" izz="0.00666" />
        </inertial>
    </link>
    <link name="left_upper_arm_link">
        <visual>
            <origin rpy="1.5707963267948966 0 -1.5707963267948966" xyz="0 0 0.138" />
            <geometry>
                <mesh filename="package://arm_robot_description/meshes/ur5e/visual/upperarm.dae" />
            </geometry>
            <material name="LightGrey">
                <color rgba="0.7 0.7 0.7 1.0" />
            </material>
        </visual>
        <collision>
            <origin rpy="1.5707963267948966 0 -1.5707963267948966" xyz="0 0 0.138" />
            <geometry>
                <mesh filename="package://arm_robot_description/meshes/ur5e/collision/upperarm.stl" />
            </geometry>
        </collision>
        <inertial>
            <mass value="8.393" />
            <origin rpy="0 1.5707963267948966 0" xyz="-0.2125 0.0 0.138" />
            <inertia ixx="0.1338857818623325" ixy="0.0" ixz="0.0" iyy="0.1338857818623325" iyz="0.0" izz="0.0151074" />
        </inertial>
    </link>
    <link name="left_forearm_link">
        <visual>
            <origin rpy="1.5707963267948966 0 -1.5707963267948966" xyz="0 0 0.007" />
            <geometry>
                <mesh filename="package://arm_robot_description/meshes/ur5e/visual/forearm.dae" />
            </geometry>
            <material name="LightGrey">
                <color rgba="0.7 0.7 0.7 1.0" />
            </material>
        </visual>
        <collision>
            <origin rpy="1.5707963267948966 0 -1.5707963267948966" xyz="0 0 0.007" />
            <geometry>
                <mesh filename="package://arm_robot_description/meshes/ur5e/collision/forearm.stl" />
            </geometry>
        </collision>
        <inertial>
            <mass value="2.275" />
            <origin rpy="0 1.5707963267948966 0" xyz="-0.1961 0.0 0.007" />
            <inertia ixx="0.031209355099586295" ixy="0.0" ixz="0.0" iyy="0.031209355099586295" iyz="0.0" izz="0.004095" />
        </inertial>
    </link>
    <link name="left_wrist_1_link">
        <visual>
            <!-- TODO: Move this to a parameter -->
            <origin rpy="1.5707963267948966 0 0" xyz="0 0 -0.127" />
            <geometry>
                <mesh filename="package://arm_robot_description/meshes/ur5e/visual/wrist1.dae" />
            </geometry>
            <material name="LightGrey">
                <color rgba="0.7 0.7 0.7 1.0" />
            </material>
        </visual>
        <collision>
            <origin rpy="1.5707963267948966 0 0" xyz="0 0 -0.127" />
            <geometry>
                <mesh filename="package://arm_robot_description/meshes/ur5e/collision/wrist1.stl" />
            </geometry>
        </collision>
        <inertial>
            <mass value="1.219" />
            <origin rpy="0 0 0" xyz="0 0 0" />
            <inertia ixx="0.0025598989760400002" ixy="0.0" ixz="0.0" iyy="0.0025598989760400002" iyz="0.0" izz="0.0021942" />
        </inertial>
    </link>
    <link name="left_wrist_2_link">
        <visual>
            <origin rpy="0 0 0" xyz="0 0 -0.0997" />
            <geometry>
                <mesh filename="package://arm_robot_description/meshes/ur5e/visual/wrist2.dae" />
            </geometry>
            <material name="LightGrey">
                <color rgba="0.7 0.7 0.7 1.0" />
            </material>
        </visual>
        <collision>
            <origin rpy="0 0 0" xyz="0 0 -0.0997" />
            <geometry>
                <mesh filename="package://arm_robot_description/meshes/ur5e/collision/wrist2.stl" />
            </geometry>
        </collision>
        <inertial>
            <mass value="1.219" />
            <origin rpy="0 0 0" xyz="0 0 0" />
            <inertia ixx="0.0025598989760400002" ixy="0.0" ixz="0.0" iyy="0.0025598989760400002" iyz="0.0" izz="0.0021942" />
        </inertial>
    </link>
    <link name="left_wrist_3_link">
        <visual>
            <origin rpy="1.5707963267948966 0 0" xyz="0 0 -0.0989" />
            <geometry>
                <mesh filename="package://arm_robot_description/meshes/ur5e/visual/wrist3.dae" />
            </geometry>
            <material name="LightGrey">
                <color rgba="0.7 0.7 0.7 1.0" />
            </material>
        </visual>
        <collision>
            <origin rpy="1.5707963267948966 0 0" xyz="0 0 -0.0989" />
            <geometry>
                <mesh filename="package://arm_robot_description/meshes/ur5e/collision/wrist3.stl" />
            </geometry>
        </collision>
        <inertial>
            <mass value="0.1879" />
            <origin rpy="0 0 0" xyz="0.0 0.0 -0.0229" />
            <inertia ixx="9.890410052167731e-05" ixy="0.0" ixz="0.0" iyy="9.890410052167731e-05" iyz="0.0" izz="0.0001321171875" />
        </inertial>
    </link>
    <!-- joints: main serial chain -->
    <joint name="left_base_link-base_link_inertia" type="fixed">
        <parent link="left_base_link" />
        <child link="left_base_link_inertia" />
        <!-- 'base_link' is REP-103 aligned (so X+ forward), while the internal
           frames of the robot/controller have X+ pointing backwards.
           Use the joint between 'base_link' and 'base_link_inertia' (a dummy
           link/frame) to introduce the necessary rotation over Z (of pi rad).
      -->
        <origin rpy="0 0 3.141592653589793" xyz="0 0 0" />
    </joint>
    <joint name="left_shoulder_pan_joint" type="revolute">
        <parent link="left_base_link_inertia" />
        <child link="left_shoulder_link" />
        <origin rpy="0 0 5.921646436743422e-08" xyz="0 0 0.1627297657342701" />
        <axis xyz="0 0 1" />
        <limit effort="150.0" lower="-6.283185307179586" upper="6.283185307179586" velocity="3.141592653589793" />
        <dynamics damping="0" friction="0" />
    </joint>
    <joint name="left_shoulder_lift_joint" type="revolute">
        <parent link="left_shoulder_link" />
        <child link="left_upper_arm_link" />
        <origin rpy="1.571350908778415 0 -3.085572842734852e-06" xyz="0.0001588353640365326 0 0" />
        <axis xyz="0 0 1" />
        <limit effort="150.0" lower="-6.283185307179586" upper="6.283185307179586" velocity="3.141592653589793" />
        <dynamics damping="0" friction="0" />
    </joint>
    <joint name="left_elbow_joint" type="revolute">
        <parent link="left_upper_arm_link" />
        <child link="left_forearm_link" />
        <origin rpy="0.0003200011350069759 -0.0002227248904285447 -1.085352311177093e-06" xyz="-0.4251005603256471 0 0" />
        <axis xyz="0 0 1" />
        <limit effort="150.0" lower="-3.141592653589793" upper="3.141592653589793" velocity="3.141592653589793" />
        <dynamics damping="0" friction="0" />
    </joint>
    <joint name="left_wrist_1_joint" type="revolute">
        <parent link="left_forearm_link" />
        <child link="left_wrist_1_link" />
        <origin rpy="0.007922150818238065 0.0001913312126438064 -2.456957013920244e-06" xyz="-0.3922314444721665 -0.001059811827050482 0.1337754960543269" />
        <axis xyz="0 0 1" />
        <limit effort="28.0" lower="-6.283185307179586" upper="6.283185307179586" velocity="3.141592653589793" />
        <dynamics damping="0" friction="0" />
    </joint>
    <joint name="left_wrist_2_joint" type="revolute">
        <parent link="left_wrist_1_link" />
        <child link="left_wrist_2_link" />
        <origin rpy="1.569787769915148 0 4.196170326140058e-08" xyz="-8.543141610977271e-05 -0.09959947723388803 0.0001004517720430495" />
        <axis xyz="0 0 1" />
        <limit effort="28.0" lower="-6.283185307179586" upper="6.283185307179586" velocity="3.141592653589793" />
        <dynamics damping="0" friction="0" />
    </joint>
    <joint name="left_wrist_3_joint" type="revolute">
        <parent link="left_wrist_2_link" />
        <child link="left_wrist_3_link" />
        <origin rpy="1.570601435882507 3.141592653589793 3.141592438200498" xyz="7.159022188747432e-05 0.09955984828462842 -1.940330991524593e-05" />
        <axis xyz="0 0 1" />
        <limit effort="28.0" lower="-6.283185307179586" upper="6.283185307179586" velocity="3.141592653589793" />
        <dynamics damping="0" friction="0" />
    </joint>
    <!-- ROS-Industrial 'base' frame: base_link to UR 'Base' Coordinates transform -->
    <link name="left_base" />
    <joint name="left_base_link-base_fixed_joint" type="fixed">
        <!-- Note the rotation over Z of pi radians: as base_link is REP-103
           aligned (ie: has X+ forward, Y+ left and Z+ up), this is needed
           to correctly align 'base' with the 'Base' coordinate system of
           the UR controller.
      -->
        <origin rpy="0 0 3.141592653589793" xyz="0 0 0" />
        <parent link="left_base_link" />
        <child link="left_base" />
    </joint>
    <!-- ROS-Industrial 'flange' frame: attachment point for EEF models -->
    <link name="left_flange" />
    <joint name="left_wrist_3-flange" type="fixed">
        <parent link="left_wrist_3_link" />
        <child link="left_flange" />
        <origin rpy="0 -1.5707963267948966 -1.5707963267948966" xyz="0 0 0" />
    </joint>
    <!-- ROS-Industrial 'tool0' frame: all-zeros tool frame -->
    <link name="left_tool0" />
    <joint name="left_flange-tool0" type="fixed">
        <!-- default toolframe: X+ left, Y+ up, Z+ front -->
        <origin rpy="1.5707963267948966 0 1.5707963267948966" xyz="0.0 0 0" />
        <parent link="left_flange" />
        <child link="left_tool0" />
    </joint>
    <joint name="left_virtual_fixed" type="fixed">
        <parent link="left_correct_link" />
        <child link="left_base_link" />
        <!-- 虚拟关节修正 -->
        <origin rpy="0.0 0.0 0.0" xyz="0.0 0.0 0.0" />
    </joint>
    <link name="right_dh_base_link">
        <inertial>
            <origin rpy="0 0 0" xyz="-2.97896383687117E-05 -0.00119414606853069 0.0383013066202999" />
            <mass value="0.407689241604604" />
            <inertia ixx="0.000382601149885368" ixy="-2.00188830802339E-08" ixz="-2.74934362808617E-08" iyy="0.000182283012175943" iyz="2.92748971762364E-07" izz="0.000433183926992861" />
        </inertial>
        <visual>
            <origin rpy="0 0 0" xyz="0 0 0" />
            <geometry>
                <mesh filename="package://ur_gazebo/meshes/dh_pgi/dh_base_link.STL" />
            </geometry>
            <material name="light_grey">
                <color rgba="1 1 1 1" />
            </material>
        </visual>
        <collision>
            <origin rpy="0 0 0" xyz="0 0 0" />
            <geometry>
                <mesh filename="package://ur_gazebo/meshes/dh_pgi/dh_base_link.STL" />
            </geometry>
        </collision>
    </link>
    <link name="right_dh_finger1_link">
        <inertial>
            <origin rpy="0 0 0" xyz="0.00194790394990391 0.00918650753677023 0.00947748977599767" />
            <mass value="0.0589543896992846" />
            <inertia ixx="2.37128965154064E-05" ixy="3.83269385718325E-06" ixz="4.94815116549899E-06" iyy="3.37272907966156E-05" iyz="-4.62772008724202E-06" izz="1.98369145830284E-05" />
        </inertial>
        <visual>
            <origin rpy="0 0 0" xyz="0 0 0" />
            <geometry>
                <mesh filename="package://ur_gazebo/meshes/dh_pgi/dh_finger1_link.STL" />
            </geometry>
            <material name="light_grey">
                <color rgba="1 1 1 1" />
            </material>
        </visual>
        <collision>
            <origin rpy="0 0 0" xyz="0 0 0" />
            <geometry>
                <mesh filename="package://ur_gazebo/meshes/dh_pgi/dh_finger1_link.STL" />
            </geometry>
        </collision>
    </link>
    <gazebo reference="right_dh_finger1_link">
        <implicitSpringDamper>1</implicitSpringDamper>
        <mu1>100000</mu1>
        <mu2>100000</mu2>
        <kp>100000000.0</kp>
        <kd>1.0</kd>
        <plugin name="gazebo_ros_control" filename="libgazebo_ros_control.so">
            <robotNamespace>/</robotNamespace>
        </plugin>
    </gazebo>
    <joint name="right_dh_base_finger1_joint" type="prismatic">
        <origin rpy="0 0 -1.5708" xyz="-0.0184 0.0 0.09325" />
        <parent link="right_dh_base_link" />
        <child link="right_dh_finger1_link" />
        <axis xyz="-1 0 0" />
        <limit effort="30" lower="0" upper="0.04" velocity="0.5" />
    </joint>
    <link name="right_dh_finger2_link">
        <inertial>
            <origin rpy="0 0 0" xyz="0.00194790394990389 0.00918650753677023 0.00947748977599765" />
            <mass value="0.0589543896992846" />
            <inertia ixx="2.37128965154064E-05" ixy="3.83269385718325E-06" ixz="4.94815116549898E-06" iyy="3.37272907966157E-05" iyz="-4.62772008724202E-06" izz="1.98369145830284E-05" />
        </inertial>
        <visual>
            <origin rpy="0 0 0" xyz="0 0 0" />
            <geometry>
                <mesh filename="package://ur_gazebo/meshes/dh_pgi/dh_finger2_link.STL" />
            </geometry>
            <material name="light_grey">
                <color rgba="1 1 1 1" />
            </material>
        </visual>
        <collision>
            <origin rpy="0 0 0" xyz="0 0 0" />
            <geometry>
                <mesh filename="package://ur_gazebo/meshes/dh_pgi/dh_finger2_link.STL" />
            </geometry>
        </collision>
    </link>
    <gazebo reference="right_dh_finger2_link">
        <implicitSpringDamper>1</implicitSpringDamper>
        <mu1>100000</mu1>
        <mu2>100000</mu2>
        <kp>100000000.0</kp>
        <kd>1.0</kd>
    </gazebo>
    <joint name="right_dh_base_finger2_joint" type="prismatic">
        <origin rpy="0 0 1.5708" xyz="0.0184 -0.0 0.09325" />
        <parent link="right_dh_base_link" />
        <child link="right_dh_finger2_link" />
        <axis xyz="-1 0 0" />
        <limit effort="20" lower="0" upper="0.04" velocity="0.5" />
        <mimic joint="right_dh_base_finger1_joint" multiplier="1" offset="0" />
    </joint>
    <link name="right_dh_center_link" />
    <joint name="right_dh_base_center_joint" type="fixed">
        <origin rpy="3.1416 -1.5708 0" xyz="0 0 0.14124" />
        <parent link="right_dh_base_link" />
        <child link="right_dh_center_link" />
        <axis xyz="0 0 0" />
    </joint>
    <link name="right_dh_load1_link" />
    <joint name="right_dh_base_load1_joint" type="fixed">
        <origin rpy="3.1416 -1.5708 0" xyz="-0.030325 0 0.0619" />
        <parent link="right_dh_base_link" />
        <child link="right_dh_load1_link" />
        <axis xyz="0 0 0" />
    </joint>
    <transmission name="right_dh_base_finger1_trans">
        <type>transmission_interface/SimpleTransmission</type>
        <joint name="right_dh_base_finger1_joint">
            <hardwareInterface>hardware_interface/PositionJointInterface</hardwareInterface>
        </joint>
        <actuator name="right_dh_base_finger1_motor">
            <mechanicalReduction>1</mechanicalReduction>
            <hardwareInterface>hardware_interface/PositionJointInterface</hardwareInterface>
        </actuator>
    </transmission>
    <!--libroboticsgroup_gazebo_mimic_joint_plugin.so loading plugin: mimic joints works in gazebo now  libroboticsgroup_upatras_gazebo_mimic_joint_plugin.so-->
    <gazebo>
        <plugin filename="libroboticsgroup_upatras_gazebo_mimic_joint_plugin.so" name="right_mimic_dh_robotics_ag95_1">
            <joint>right_dh_base_finger1_joint</joint>
            <mimicJoint>right_dh_base_finger2_joint</mimicJoint>
            <multiplier>1.0</multiplier>
            <offset>0.0</offset>
        </plugin>
    </gazebo>
    <!-- <gazebo>
        <plugin filename="libroboticsgroup_gazebo_mimic_joint_plugin.so" name="${prefix}mimic_dh_robotics_ag95_1">
            <joint>${prefix}dh_base_finger1_joint</joint>
            <mimicJoint>${prefix}dh_base_finger2_joint</mimicJoint>
            <multiplier>1.0</multiplier>
            <offset>0.0</offset>
        </plugin>
    </gazebo> -->
    <joint name="right_gripper_joint" type="fixed">
        <parent link="right_tool0" />
        <child link="right_dh_base_link" />
        <origin rpy="0 0 -1.5707963" xyz="0 0 0.006" />
    </joint>
    <link name="left_cylinder_link">
        <visual>
            <geometry>
                <cylinder length="0.03" radius="0.023" />
            </geometry>
            <origin rpy="0 0 0" xyz="0 0 0.015" />
            <material name="grey" />
        </visual>
        <collision>
            <geometry>
                <cylinder length="0.03" radius="0.023" />
            </geometry>
            <origin rpy="0 0 0" xyz="0 0 0.015" />
        </collision>
        <inertial>
            <mass value="0.1" />
            <origin xyz="0 0 0" rpy="0 0 0" />
            <inertia ixx="0.03" iyy="0.03" izz="0.03" ixy="0.0" ixz="0.0" iyz="0.0" />
        </inertial>
    </link>
    <!-- 定义圆柱连接到correct_link的关节 -->
    <joint name="left_cylinder_joint" type="fixed">
        <parent link="left_tool0" />
        <child link="left_cylinder_link" />
        <origin rpy="0 0 0" xyz="0 0 0" />
    </joint>
    <link name="left_dh_base_link">
        <inertial>
            <origin rpy="0 0 0" xyz="-2.97896383687117E-05 -0.00119414606853069 0.0383013066202999" />
            <mass value="0.407689241604604" />
            <inertia ixx="0.000382601149885368" ixy="-2.00188830802339E-08" ixz="-2.74934362808617E-08" iyy="0.000182283012175943" iyz="2.92748971762364E-07" izz="0.000433183926992861" />
        </inertial>
        <visual>
            <origin rpy="0 0 0" xyz="0 0 0" />
            <geometry>
                <mesh filename="package://ur_gazebo/meshes/dh_pgi/dh_base_link.STL" />
            </geometry>
            <material name="light_grey">
                <color rgba="1 1 1 1" />
            </material>
        </visual>
        <collision>
            <origin rpy="0 0 0" xyz="0 0 0" />
            <geometry>
                <mesh filename="package://ur_gazebo/meshes/dh_pgi/dh_base_link.STL" />
            </geometry>
        </collision>
    </link>
    <link name="left_dh_finger1_link">
        <inertial>
            <origin rpy="0 0 0" xyz="0.00194790394990391 0.00918650753677023 0.00947748977599767" />
            <mass value="0.0589543896992846" />
            <inertia ixx="2.37128965154064E-05" ixy="3.83269385718325E-06" ixz="4.94815116549899E-06" iyy="3.37272907966156E-05" iyz="-4.62772008724202E-06" izz="1.98369145830284E-05" />
        </inertial>
        <visual>
            <origin rpy="0 0 0" xyz="0 0 0" />
            <geometry>
                <mesh filename="package://ur_gazebo/meshes/dh_pgi/dh_finger1_link.STL" />
            </geometry>
            <material name="light_grey">
                <color rgba="1 1 1 1" />
            </material>
        </visual>
        <collision>
            <origin rpy="0 0 0" xyz="0 0 0" />
            <geometry>
                <mesh filename="package://ur_gazebo/meshes/dh_pgi/dh_finger1_link.STL" />
            </geometry>
        </collision>
    </link>
    <gazebo reference="left_dh_finger1_link">
        <implicitSpringDamper>1</implicitSpringDamper>
        <mu1>100000</mu1>
        <mu2>100000</mu2>
        <kp>100000000.0</kp>
        <kd>1.0</kd>
    </gazebo>
    <joint name="left_dh_base_finger1_joint" type="prismatic">
        <origin rpy="0 0 -1.5708" xyz="-0.0184 0.0 0.09325" />
        <parent link="left_dh_base_link" />
        <child link="left_dh_finger1_link" />
        <axis xyz="-1 0 0" />
        <limit effort="30" lower="0" upper="0.04" velocity="0.5" />
    </joint>
    <link name="left_dh_finger2_link">
        <inertial>
            <origin rpy="0 0 0" xyz="0.00194790394990389 0.00918650753677023 0.00947748977599765" />
            <mass value="0.0589543896992846" />
            <inertia ixx="2.37128965154064E-05" ixy="3.83269385718325E-06" ixz="4.94815116549898E-06" iyy="3.37272907966157E-05" iyz="-4.62772008724202E-06" izz="1.98369145830284E-05" />
        </inertial>
        <visual>
            <origin rpy="0 0 0" xyz="0 0 0" />
            <geometry>
                <mesh filename="package://ur_gazebo/meshes/dh_pgi/dh_finger2_link.STL" />
            </geometry>
            <material name="light_grey">
                <color rgba="1 1 1 1" />
            </material>
        </visual>
        <collision>
            <origin rpy="0 0 0" xyz="0 0 0" />
            <geometry>
                <mesh filename="package://ur_gazebo/meshes/dh_pgi/dh_finger2_link.STL" />
            </geometry>
        </collision>
    </link>
    <gazebo reference="left_dh_finger2_link">
        <implicitSpringDamper>1</implicitSpringDamper>
        <mu1>100000</mu1>
        <mu2>100000</mu2>
        <kp>100000000.0</kp>
        <kd>1.0</kd>
    </gazebo>
    <joint name="left_dh_base_finger2_joint" type="prismatic">
        <origin rpy="0 0 1.5708" xyz="0.0184 -0.0 0.09325" />
        <parent link="left_dh_base_link" />
        <child link="left_dh_finger2_link" />
        <axis xyz="-1 0 0" />
        <limit effort="20" lower="0" upper="0.04" velocity="0.5" />
        <mimic joint="left_dh_base_finger1_joint" multiplier="1" offset="0" />
    </joint>
    <link name="left_dh_center_link" />
    <joint name="left_dh_base_center_joint" type="fixed">
        <origin rpy="3.1416 -1.5708 0" xyz="0 0 0.14124" />
        <parent link="left_dh_base_link" />
        <child link="left_dh_center_link" />
        <axis xyz="0 0 0" />
    </joint>
    <link name="left_dh_load1_link" />
    <joint name="left_dh_base_load1_joint" type="fixed">
        <origin rpy="3.1416 -1.5708 0" xyz="-0.030325 0 0.0619" />
        <parent link="left_dh_base_link" />
        <child link="left_dh_load1_link" />
        <axis xyz="0 0 0" />
    </joint>
    <transmission name="left_dh_base_finger1_trans">
        <type>transmission_interface/SimpleTransmission</type>
        <joint name="left_dh_base_finger1_joint">
            <hardwareInterface>hardware_interface/PositionJointInterface</hardwareInterface>
        </joint>
        <actuator name="left_dh_base_finger1_motor">
            <mechanicalReduction>1</mechanicalReduction>
            <hardwareInterface>hardware_interface/PositionJointInterface</hardwareInterface>
        </actuator>
    </transmission>
    <!--libroboticsgroup_gazebo_mimic_joint_plugin.so loading plugin: mimic joints works in gazebo now  libroboticsgroup_upatras_gazebo_mimic_joint_plugin.so-->
    <gazebo>
        <plugin filename="libroboticsgroup_upatras_gazebo_mimic_joint_plugin.so" name="left_mimic_dh_robotics_ag95_1">
            <joint>left_dh_base_finger1_joint</joint>
            <mimicJoint>left_dh_base_finger2_joint</mimicJoint>
            <multiplier>1.0</multiplier>
            <offset>0.0</offset>
        </plugin>
    </gazebo>
    <!-- <gazebo>
        <plugin filename="libroboticsgroup_gazebo_mimic_joint_plugin.so" name="${prefix}mimic_dh_robotics_ag95_1">
            <joint>${prefix}dh_base_finger1_joint</joint>
            <mimicJoint>${prefix}dh_base_finger2_joint</mimicJoint>
            <multiplier>1.0</multiplier>
            <offset>0.0</offset>
        </plugin>
    </gazebo> -->
    <joint name="left_gripper_joint" type="fixed">
        <parent link="left_cylinder_link" />
        <child link="left_dh_base_link" />
        <!-- <origin xyz="0 0 0.031" rpy="0 1.5707963 3.141592653"/> -->
        <origin rpy="0 0 -1.5707963" xyz="0 0 0.03" />
        <!-- <origin xyz="0 0 0.047" rpy="0 1.5707963 3.141592653"/> -->
    </joint>
    <link name="right_tool_base_link">
        <inertial>
            <origin rpy="0 0 0" xyz="-0.01085 4.4441E-09 0.01005" />
            <mass value="0.021763" />
            <inertia ixx="8.355E-06" ixy="2.7897E-14" ixz="1.1022E-06" iyy="4.1504E-06" iyz="2.4783E-13" izz="7.7133E-06" />
        </inertial>
        <visual>
            <origin rpy="0 0 0" xyz="0 0 0" />
            <geometry>
                <mesh filename="package://ur_gazebo/meshes/tool_camera/tool_base_link.STL" />
            </geometry>
            <material name="">
                <color rgba="1 1 1 1" />
            </material>
        </visual>
        <collision>
            <origin rpy="0 0 0" xyz="0 0 0" />
            <geometry>
                <mesh filename="package://ur_gazebo/meshes/tool_camera/tool_base_link.STL" />
            </geometry>
        </collision>
    </link>
    <link name="right_tool_camera_base_link" />
    <joint name="right_tool_base_camera_base_joint" type="fixed">
        <origin rpy="0 0 0" xyz="-0.017 0 0.0305" />
        <parent link="right_tool_base_link" />
        <child link="right_tool_camera_base_link" />
        <axis xyz="0 0 0" />
    </joint>
    <joint name="right_tool_camera_joint" type="fixed">
        <parent link="right_dh_load1_link" />
        <child link="right_tool_base_link" />
        <origin rpy="3.141592653 0 0" xyz="0 0 0" />
    </joint>
    <link name="left_tool_base_link">
        <inertial>
            <origin rpy="0 0 0" xyz="-0.01085 4.4441E-09 0.01005" />
            <mass value="0.021763" />
            <inertia ixx="8.355E-06" ixy="2.7897E-14" ixz="1.1022E-06" iyy="4.1504E-06" iyz="2.4783E-13" izz="7.7133E-06" />
        </inertial>
        <visual>
            <origin rpy="0 0 0" xyz="0 0 0" />
            <geometry>
                <mesh filename="package://ur_gazebo/meshes/tool_camera/tool_base_link.STL" />
            </geometry>
            <material name="">
                <color rgba="1 1 1 1" />
            </material>
        </visual>
        <collision>
            <origin rpy="0 0 0" xyz="0 0 0" />
            <geometry>
                <mesh filename="package://ur_gazebo/meshes/tool_camera/tool_base_link.STL" />
            </geometry>
        </collision>
    </link>
    <link name="left_tool_camera_base_link" />
    <joint name="left_tool_base_camera_base_joint" type="fixed">
        <origin rpy="0 0 0" xyz="-0.017 0 0.0305" />
        <parent link="left_tool_base_link" />
        <child link="left_tool_camera_base_link" />
        <axis xyz="0 0 0" />
    </joint>
    <joint name="left_tool_camera_joint" type="fixed">
        <parent link="left_dh_load1_link" />
        <child link="left_tool_base_link" />
        <origin rpy="3.141592653 0 0" xyz="0 0 0" />
    </joint>
    <transmission name="trans_right_dh_base_finger2_joint">
        <type>transmission_interface/SimpleTransmission</type>
        <joint name="right_dh_base_finger2_joint">
            <hardwareInterface>hardware_interface/EffortJointInterface</hardwareInterface>
        </joint>
        <actuator name="right_dh_base_finger2_joint_motor">
            <hardwareInterface>hardware_interface/EffortJointInterface</hardwareInterface>
            <mechanicalReduction>1</mechanicalReduction>
        </actuator>
    </transmission>
    <transmission name="trans_left_dh_base_finger2_joint">
        <type>transmission_interface/SimpleTransmission</type>
        <joint name="left_dh_base_finger2_joint">
            <hardwareInterface>hardware_interface/EffortJointInterface</hardwareInterface>
        </joint>
        <actuator name="left_dh_base_finger2_joint_motor">
            <hardwareInterface>hardware_interface/EffortJointInterface</hardwareInterface>
            <mechanicalReduction>1</mechanicalReduction>
        </actuator>
    </transmission>
</robot>

